Workbook
Name Case: 'Case Studies'!$B$3
Name COGS: '[1]Step 3 Income Statement '!$13:$13
Name COGS: '[1]Step 3 Income Statement '!$13:$13
Name COGS: 'Step 3 Income Statement '!$13:$13
Name General_and_Administrative: '[1]Step 3 Income Statement '!$31:$31
Name General_and_Administrative: '[1]Step 3 Income Statement '!$31:$31
Name General_and_Administrative: 'Step 3 Income Statement '!$31:$31
Name Market_Cap: '[2]ANSWER to Question 9'!$B$4:$B$15
Name Other_Income_or_Expense: 'Step 3 Income Statement '!$50:$50
Name OtherEx: 'What We''ll Learn in Other Ex. '!$A$4
Name Research_and_Development: '[1]Step 3 Income Statement '!$25:$25
Name Research_and_Development: '[1]Step 3 Income Statement '!$25:$25
Name Research_and_Development: 'Step 3 Income Statement '!$25:$25
Name Revenue: '[1]Step 3 Income Statement '!$8:$8
Name Revenue: '[1]Step 3 Income Statement '!$8:$8
Name Revenue: 'Step 3 Income Statement '!$8:$8
Name Sales_and_Marketing: '[1]Step 3 Income Statement '!$19:$19
Name Sales_and_Marketing: '[1]Step 3 Income Statement '!$19:$19
Name Sales_and_Marketing: 'Step 3 Income Statement '!$19:$19
Name Step_1_Modeling: 'Step 1 Modeling+Valuation Rules'!$B$2
Name Step_2_Revenue: 'Step 2 Revenue Forecast'!$B$9
Name Step_3_Income_Statement: 'Step 3 Income Statement '!$C$9
Name Step_4_Balance_Sheet: 'Step 4 Balance Sheet'!$B$8
Name Step_5_Cash_Flow_Statement: 'Step 5 Cash Flow Statement'!$B$7
Name Step_6_DCF: 'Step 6 DCF Valuation'!$B$7
Name Step_7_Other: 'Step 7 Other Valuations+Compare'!$C$6

Sheet Step 1 Modeling+Valuation Rules
A1: v 2.0
G2: View Tips: For more space on your screen, please minimize the ribbon by clicking on the "^" on the top right-hand corner of your screen or zoom out using the view controls on the bottom-right hand corner of your screen.
B142: Next Step: Please click on the tab called Step 2 Revenue Forecast (or use the buttons at the top). Please remember to only change blue shaded text. Thanks

Sheet Step 2 Revenue Forecast
AK1: View Tips: For more space on your screen, please minimize the ribbon by clicking on the "^" on the top right-hand corner of your screen or zoom out using the view controls on the bottom-right hand corner of your screen.
A2: Welcome to Financial Modeling and Valuation Step 2 of 7!
A3: Change only the BLUE fonts, then go to Step 3 on the next tab.
A4: Orange Shaded Cells = Sparklines (for trend analysis) | AK4: 2013 - 2022 Annual TREND Sparklines
A5: Blue Fonts = hard coded (not calculated) | AK5: Note from Chris: Please make sure to close the groups by clicking on "1" to the left and slightly above column A or you will see quarterly numbers in this sparkline column.
A6: REVENUE BREAKDOWN (feeds into Income Statement on the next tab) $ Value in 000's | B6: 1Q13 | C6: 2Q13 | D6: 3Q13 | E6: 4Q13 | F6: 2013 | G6: 1Q14 | H6: 2Q14 | I6: 3Q14 | J6: 4Q14 | K6: 2014 | L6: 1Q15 | M6: 2Q15 | N6: 3Q15 | O6: 4Q15 | P6: 2015 | Q6: 1Q16 | R6: 2Q16 | S6: 3Q16 | T6: 4Q16 | U6: 2016 | V6: 1Q17 | W6: 2Q17 | X6: 3Q17 | Y6: 4Q17 | Z6: 2017 | AA6: 1Q18 | AB6: 2Q18 | AC6: 3Q18 | AD6: 4Q18 | AE6: 2018 | AF6: 2019 | AG6: 2020 | AH6: 2021 | AI6: 2022
A7: Sector Breakdown of Revenue
AK8: Annual Total Revenue Sparkline (top line in $ change and bottom line in % change):
A9: Total Revenue | B9: =B13+B18 -> 0 | C9: =C13+C18 -> 0 | D9: =D13+D18 -> 0 | E9: =E13+E18 -> 0 | F9: =F13+F18 -> 0 | G9: =G13+G18 -> 0 | H9: =H13+H18 -> 0 | I9: =I13+I18 -> 0 | ... AI9: =AI13+AI18 -> 0
A10: YOY change | B10: N/A | C10: N/A | D10: N/A | E10: N/A | G10: =IFERROR(G9/B9-1,"N/A") -> N/A | H10: =IFERROR(H9/C9-1,"N/A") -> N/A | I10: =IFERROR(I9/D9-1,"N/A") -> N/A | J10: =IFERROR(J9/E9-1,"N/A") -> N/A | K10: =IFERROR(K9/F9-1,"N/A") -> N/A | L10: =IFERROR(L9/G9-1,"N/A") -> N/A | M10: =IFERROR(M9/H9-1,"N/A") -> N/A | N10: =IFERROR(N9/I9-1,"N/A") -> N/A | ... AE10: =IFERROR(AE9/Z9-1,"N/A") -> N/A | AF10: =IFERROR(AF9/AE9-1,"N/A") -> N/A | AG10: =IFERROR(AG9/AF9-1,"N/A") -> N/A | AH10: =IFERROR(AH9/AG9-1,"N/A") -> N/A | AI10: =IFERROR(AI9/AH9-1,"N/A") -> N/A
A11: QOQ change | B11: N/A | C11: =IFERROR(C9/B9-1,"N/A") -> N/A | D11: =IFERROR(D9/C9-1,"N/A") -> N/A | E11: =IFERROR(E9/D9-1,"N/A") -> N/A | G11: =IFERROR(G9/E9-1,"N/A") -> N/A | H11: =IFERROR(H9/G9-1,"N/A") -> N/A | I11: =IFERROR(I9/H9-1,"N/A") -> N/A | J11: =IFERROR(J9/I9-1,"N/A") -> N/A | L11: =IFERROR(L9/J9-1,"N/A") -> N/A | M11: =IFERROR(M9/L9-1,"N/A") -> N/A | N11: =IFERROR(N9/M9-1,"N/A") -> N/A | O11: =IFERROR(O9/N9-1,"N/A") -> N/A | Q11: =IFERROR(Q9/O9-1,"N/A") -> N/A | R11: =IFERROR(R9/Q9-1,"N/A") -> N/A | S11: =IFERROR(S9/R9-1,"N/A") -> N/A | T11: =IFERROR(T9/S9-1,"N/A") -> N/A | V11: =IFERROR(V9/T9-1,"N/A") -> N/A | W11: =IFERROR(W9/V9-1,"N/A") -> N/A | X11: =IFERROR(X9/W9-1,"N/A") -> N/A | Y11: =IFERROR(Y9/X9-1,"N/A") -> N/A | AA11: =IFERROR(AA9/Y9-1,"N/A") -> N/A | AB11: =IFERROR(AB9/AA9-1,"N/A") -> N/A | AC11: =IFERROR(AC9/AB9-1,"N/A") -> N/A | AD11: =IFERROR(AD9/AC9-1,"N/A") -> N/A
A12: Quarterly Total Revenue Seasonality Sparkline (click + to see it) | AK12: Annual Revenue Line 1 of 2 Sparkline (top line in $ change and bottom line in % change):
A13: REVENUE LINE ITEM 1 OF 2 | B13: 0 | C13: 0 | D13: 0 | E13: 0 | F13: =SUM(B13:E13) -> 0 | G13: 0 | H13: 0 | I13: 0 | J13: 0 | K13: =SUM(G13:J13) -> 0 | L13: 0 | M13: 0 | N13: 0 | O13: 0 | P13: =SUM(L13:O13) -> 0 | Q13: 0 | R13: 0 | S13: 0 | T13: 0 | U13: =SUM(Q13:T13) -> 0 | V13: 0 | W13: 0 | X13: 0 | Y13: 0 | Z13: =SUM(V13:Y13) -> 0 | AA13: =V13*(1+AA14) -> 0 | AB13: =W13*(1+AB14) -> 0 | AC13: =X13*(1+AC14) -> 0 | AD13: =Y13*(1+AD14) -> 0 | AE13: =SUM(AA13:AD13) -> 0 | AF13: =IF(AF14="",0,AE13*(1+AF14)) -> 0 | AG13: =IF(AG14="",0,AF13*(1+AG14)) -> 0 | AH13: =IF(AH14="",0,AG13*(1+AH14)) -> 0 | AI13: =IF(AI14="",0,AH13*(1+AI14)) -> 0
A14: YOY change | B14: N/A | C14: N/A | D14: N/A | E14: N/A | F14: =IFERROR(F13/A13-1,"N/A") -> N/A | G14: =IFERROR(G13/B13-1,"N/A") -> N/A | H14: =IFERROR(H13/C13-1,"N/A") -> N/A | I14: =IFERROR(I13/D13-1,"N/A") -> N/A | J14: =IFERROR(J13/E13-1,"N/A") -> N/A | K14: =IFERROR(K13/F13-1,"N/A") -> N/A | L14: =IFERROR(L13/G13-1,"N/A") -> N/A | M14: =IFERROR(M13/H13-1,"N/A") -> N/A | ... Z14: =IFERROR(Z13/U13-1,"N/A") -> N/A | AA14: 0 | AB14: 0 | AC14: 0 | AD14: 0 | AE14: =IFERROR(AE13/Z13-1,"N/A") -> N/A | AF14: 0 | AG14: 0 | AH14: 0 | AI14: 0
A15: QOQ change | B15: N/A | C15: =IFERROR(C13/B13-1,"N/A") -> N/A | D15: =IFERROR(D13/C13-1,"N/A") -> N/A | E15: =IFERROR(E13/D13-1,"N/A") -> N/A | G15: =IFERROR(G13/E13-1,"N/A") -> N/A | H15: =IFERROR(H13/G13-1,"N/A") -> N/A | I15: =IFERROR(I13/H13-1,"N/A") -> N/A | J15: =IFERROR(J13/I13-1,"N/A") -> N/A | L15: =IFERROR(L13/J13-1,"N/A") -> N/A | M15: =IFERROR(M13/L13-1,"N/A") -> N/A | N15: =IFERROR(N13/M13-1,"N/A") -> N/A | O15: =IFERROR(O13/N13-1,"N/A") -> N/A | Q15: =IFERROR(Q13/O13-1,"N/A") -> N/A | R15: =IFERROR(R13/Q13-1,"N/A") -> N/A | S15: =IFERROR(S13/R13-1,"N/A") -> N/A | T15: =IFERROR(T13/S13-1,"N/A") -> N/A | V15: =IFERROR(V13/T13-1,"N/A") -> N/A | W15: =IFERROR(W13/V13-1,"N/A") -> N/A | X15: =IFERROR(X13/W13-1,"N/A") -> N/A | Y15: =IFERROR(Y13/X13-1,"N/A") -> N/A | AA15: =IFERROR(AA13/Y13-1,"N/A") -> N/A | AB15: =IFERROR(AB13/AA13-1,"N/A") -> N/A | AC15: =IFERROR(AC13/AB13-1,"N/A") -> N/A | AD15: =IFERROR(AD13/AC13-1,"N/A") -> N/A
A16: % of total | B16: =IFERROR(B13/B9,"N/A") -> N/A | C16: =IFERROR(C13/C9,"N/A") -> N/A | D16: =IFERROR(D13/D9,"N/A") -> N/A | E16: =IFERROR(E13/E9,"N/A") -> N/A | F16: =IFERROR(F13/F9,"N/A") -> N/A | G16: =IFERROR(G13/G9,"N/A") -> N/A | H16: =IFERROR(H13/H9,"N/A") -> N/A | I16: =IFERROR(I13/I9,"N/A") -> N/A | ... AI16: =IFERROR(AI13/AI9,"N/A") -> N/A
A17: Quarterly Revenue Line Item 1 of 2 Seasonality Sparkline (click + to see it) | AK17: Annual Revenue Line 2 of 2 Sparkline (top line in $ change and bottom line in % change):
A18: REVENUE LINE ITEM 2 OF 2 | B18: 0 | C18: 0 | D18: 0 | E18: 0 | F18: =SUM(B18:E18) -> 0 | G18: 0 | H18: 0 | I18: 0 | J18: 0 | K18: =SUM(G18:J18) -> 0 | L18: 0 | M18: 0 | N18: 0 | O18: 0 | P18: =SUM(L18:O18) -> 0 | Q18: 0 | R18: 0 | S18: 0 | T18: 0 | U18: =SUM(Q18:T18) -> 0 | V18: 0 | W18: 0 | X18: 0 | Y18: 0 | Z18: =SUM(V18:Y18) -> 0 | AA18: =IF(AA19="",0,V18*(1+AA19)) -> 0 | AB18: =IF(AB19="",0,W18*(1+AB19)) -> 0 | AC18: =IF(AC19="",0,X18*(1+AC19)) -> 0 | AD18: =IF(AD19="",0,Y18*(1+AD19)) -> 0 | AE18: =SUM(AA18:AD18) -> 0 | AF18: =IF(AF19="",0,AE18*(1+AF19)) -> 0 | AG18: =IF(AG19="",0,AF18*(1+AG19)) -> 0 | AH18: =IF(AH19="",0,AG18*(1+AH19)) -> 0 | AI18: =IF(AI19="",0,AH18*(1+AI19)) -> 0
A19: YOY change | B19: N/A | C19: N/A | D19: N/A | E19: N/A | G19: =IFERROR(G18/B18-1,"N/A") -> N/A | H19: =IFERROR(H18/C18-1,"N/A") -> N/A | I19: =IFERROR(I18/D18-1,"N/A") -> N/A | J19: =IFERROR(J18/E18-1,"N/A") -> N/A | K19: =IFERROR(K18/F18-1,"N/A") -> N/A | L19: =IFERROR(L18/G18-1,"N/A") -> N/A | M19: =IFERROR(M18/H18-1,"N/A") -> N/A | N19: =IFERROR(N18/I18-1,"N/A") -> N/A | ... Z19: =IFERROR(Z18/U18-1,"N/A") -> N/A | AA19: 0 | AB19: 0 | AC19: 0 | AD19: 0 | AE19: =IFERROR(AE18/Z18-1,"N/A") -> N/A | AF19: 0 | AG19: 0 | AH19: 0 | AI19: 0
A20: QOQ change | B20: N/A | C20: =IFERROR(C18/B18-1,"N/A") -> N/A | D20: =IFERROR(D18/C18-1,"N/A") -> N/A | E20: =IFERROR(E18/D18-1,"N/A") -> N/A | G20: =IFERROR(G18/E18-1,"N/A") -> N/A | H20: =IFERROR(H18/G18-1,"N/A") -> N/A | I20: =IFERROR(I18/H18-1,"N/A") -> N/A | J20: =IFERROR(J18/I18-1,"N/A") -> N/A | L20: =IFERROR(L18/J18-1,"N/A") -> N/A | M20: =IFERROR(M18/L18-1,"N/A") -> N/A | N20: =IFERROR(N18/M18-1,"N/A") -> N/A | O20: =IFERROR(O18/N18-1,"N/A") -> N/A | Q20: =IFERROR(Q18/O18-1,"N/A") -> N/A | R20: =IFERROR(R18/Q18-1,"N/A") -> N/A | S20: =IFERROR(S18/R18-1,"N/A") -> N/A | T20: =IFERROR(T18/S18-1,"N/A") -> N/A | V20: =IFERROR(V18/T18-1,"N/A") -> N/A | W20: =IFERROR(W18/V18-1,"N/A") -> N/A | X20: =IFERROR(X18/W18-1,"N/A") -> N/A | Y20: =IFERROR(Y18/X18-1,"N/A") -> N/A | AA20: =IFERROR(AA18/Y18-1,"N/A") -> N/A | AB20: =IFERROR(AB18/AA18-1,"N/A") -> N/A | AC20: =IFERROR(AC18/AB18-1,"N/A") -> N/A | AD20: =IFERROR(AD18/AC18-1,"N/A") -> N/A
A21: % of total | B21: =IFERROR(B18/B9,"N/A") -> N/A | C21: =IFERROR(C18/C9,"N/A") -> N/A | D21: =IFERROR(D18/D9,"N/A") -> N/A | E21: =IFERROR(E18/E9,"N/A") -> N/A | F21: =IFERROR(F18/F9,"N/A") -> N/A | G21: =IFERROR(G18/G9,"N/A") -> N/A | H21: =IFERROR(H18/H9,"N/A") -> N/A | I21: =IFERROR(I18/I9,"N/A") -> N/A | ... AI21: =IFERROR(AI18/AI9,"N/A") -> N/A
A22: Quarterly Revenue Line Item 2 of 2 Seasonality Sparkline (click + to see it)
A25: Next Step: Please click on the tab called Step 3 Income Statement (or use the buttons at the top). Please remember to only change blue shaded text. Thanks

Sheet Step 3 Income Statement 
AL1: View Tips: For more space on your screen, please minimize the ribbon by clicking on the "^" on the top right-hand corner of your screen or zoom out using the view controls on the bottom-right hand corner of your screen.
A2: Welcome to Financial Modeling and Valuation Step 3 of 7! | AL2: 2013 - 2022 Annual TREND Sparklines
A3: Change only the BLUE fonts, then go to Step 4 on the next tab. | AL3: Note from Chris: Please make sure to close the groups by clicking on "1" to the left and slightly above column A or you will see quarterly numbers in this sparkline column.
A4: Orange Shaded Cells = Sparklines (for trend analysis)
A5: Blue Fonts = hard coded (not calculated)
A6: Green = links to data from another tab
A7: INCOME STATEMENT $ Value in 000's | C7: ='Step 2 Revenue Forecast'!B6 -> 1Q13 | D7: ='Step 2 Revenue Forecast'!C6 -> 2Q13 | E7: ='Step 2 Revenue Forecast'!D6 -> 3Q13 | F7: ='Step 2 Revenue Forecast'!E6 -> 4Q13 | G7: ='Step 2 Revenue Forecast'!F6 -> 2013 | H7: ='Step 2 Revenue Forecast'!G6 -> 1Q14 | I7: ='Step 2 Revenue Forecast'!H6 -> 2Q14 | J7: ='Step 2 Revenue Forecast'!I6 -> 3Q14 | ... AJ7: ='Step 2 Revenue Forecast'!AI6 -> 2022 | AL7: ="Annual "&A8& " Sparkline (top line in $ change and bottom line in % change): " -> Annual Revenue Sparkline (top line in $ change and bottom line in % change):
A8: Revenue | C8: ='Step 2 Revenue Forecast'!B9 -> 0 | D8: ='Step 2 Revenue Forecast'!C9 -> 0 | E8: ='Step 2 Revenue Forecast'!D9 -> 0 | F8: ='Step 2 Revenue Forecast'!E9 -> 0 | G8: =SUM(C8:F8) -> 0 | H8: ='Step 2 Revenue Forecast'!G9 -> 0 | I8: ='Step 2 Revenue Forecast'!H9 -> 0 | J8: ='Step 2 Revenue Forecast'!I9 -> 0 | K8: ='Step 2 Revenue Forecast'!J9 -> 0 | L8: =SUM(H8:K8) -> 0 | M8: ='Step 2 Revenue Forecast'!L9 -> 0 | N8: ='Step 2 Revenue Forecast'!M9 -> 0 | O8: ='Step 2 Revenue Forecast'!N9 -> 0 | P8: ='Step 2 Revenue Forecast'!O9 -> 0 | Q8: =SUM(M8:P8) -> 0 | R8: ='Step 2 Revenue Forecast'!Q9 -> 0 | S8: ='Step 2 Revenue Forecast'!R9 -> 0 | T8: ='Step 2 Revenue Forecast'!S9 -> 0 | U8: ='Step 2 Revenue Forecast'!T9 -> 0 | V8: =SUM(R8:U8) -> 0 | W8: ='Step 2 Revenue Forecast'!V9 -> 0 | X8: ='Step 2 Revenue Forecast'!W9 -> 0 | Y8: ='Step 2 Revenue Forecast'!X9 -> 0 | Z8: ='Step 2 Revenue Forecast'!Y9 -> 0 | AA8: =SUM(W8:Z8) -> 0 | AB8: ='Step 2 Revenue Forecast'!AA9 -> 0 | AC8: ='Step 2 Revenue Forecast'!AB9 -> 0 | AD8: ='Step 2 Revenue Forecast'!AC9 -> 0 | AE8: ='Step 2 Revenue Forecast'!AD9 -> 0 | AF8: ='Step 2 Revenue Forecast'!AE9 -> 0 | AG8: ='Step 2 Revenue Forecast'!AF9 -> 0 | AH8: ='Step 2 Revenue Forecast'!AG9 -> 0 | AI8: ='Step 2 Revenue Forecast'!AH9 -> 0 | AJ8: ='Step 2 Revenue Forecast'!AI9 -> 0
A9: YOY change | C9: N/A | D9: N/A | E9: N/A | F9: N/A | H9: =IFERROR(H8/C8-1,"N/A") -> N/A | I9: =IFERROR(I8/D8-1,"N/A") -> N/A | J9: =IFERROR(J8/E8-1,"N/A") -> N/A | K9: =IFERROR(K8/F8-1,"N/A") -> N/A | L9: =IFERROR(L8/G8-1,"N/A") -> N/A | M9: =IFERROR(M8/H8-1,"N/A") -> N/A | N9: =IFERROR(N8/I8-1,"N/A") -> N/A | O9: =IFERROR(O8/J8-1,"N/A") -> N/A | ... AF9: =IFERROR(AF8/AA8-1,"N/A") -> N/A | AG9: =IFERROR(AG8/AF8-1,"N/A") -> N/A | AH9: =IFERROR(AH8/AG8-1,"N/A") -> N/A | AI9: =IFERROR(AI8/AH8-1,"N/A") -> N/A | AJ9: =IFERROR(AJ8/AI8-1,"N/A") -> N/A
A10: QOQ change | C10: N/A | D10: =IFERROR(D8/C8-1,"N/A") -> N/A | E10: =IFERROR(E8/D8-1,"N/A") -> N/A | F10: =IFERROR(F8/E8-1,"N/A") -> N/A | H10: =IFERROR(H8/F8-1,"N/A") -> N/A | I10: =IFERROR(I8/H8-1,"N/A") -> N/A | J10: =IFERROR(J8/I8-1,"N/A") -> N/A | K10: =IFERROR(K8/J8-1,"N/A") -> N/A | M10: =IFERROR(M8/K8-1,"N/A") -> N/A | N10: =IFERROR(N8/M8-1,"N/A") -> N/A | O10: =IFERROR(O8/N8-1,"N/A") -> N/A | P10: =IFERROR(P8/O8-1,"N/A") -> N/A | R10: =IFERROR(R8/P8-1,"N/A") -> N/A | S10: =IFERROR(S8/R8-1,"N/A") -> N/A | T10: =IFERROR(T8/S8-1,"N/A") -> N/A | U10: =IFERROR(U8/T8-1,"N/A") -> N/A | W10: =IFERROR(W8/U8-1,"N/A") -> N/A | X10: =IFERROR(X8/W8-1,"N/A") -> N/A | Y10: =IFERROR(Y8/X8-1,"N/A") -> N/A | Z10: =IFERROR(Z8/Y8-1,"N/A") -> N/A | AB10: =IFERROR(AB8/Z8-1,"N/A") -> N/A | AC10: =IFERROR(AC8/AB8-1,"N/A") -> N/A | AD10: =IFERROR(AD8/AC8-1,"N/A") -> N/A | AE10: =IFERROR(AE8/AD8-1,"N/A") -> N/A
A11: ="Quarterly "&A8&" Sparkline (click '2' above A1 to see it)." -> Quarterly Revenue Sparkline (click '2' above A1 to see it).
AL12: ="Annual "&A13& " Sparkline (top line in $ change and bottom line in % of revenue): " -> Annual COGS Sparkline (top line in $ change and bottom line in % of revenue):
A13: COGS | C13: 0 | D13: =D8*0.333 -> 0 | E13: =E8*0.333 -> 0 | F13: =F8*0.333 -> 0 | G13: =SUM(C13:F13) -> 0 | H13: =H8*0.333 -> 0 | I13: =I8*0.333 -> 0 | J13: =J8*0.333 -> 0 | K13: =K8*0.333 -> 0 | L13: =SUM(H13:K13) -> 0 | M13: =M8*0.333 -> 0 | N13: =N8*0.333 -> 0 | O13: =O8*0.333 -> 0 | P13: =P8*0.333 -> 0 | Q13: =SUM(M13:P13) -> 0 | R13: =R8*0.333 -> 0 | S13: =S8*0.333 -> 0 | T13: =T8*0.333 -> 0 | U13: =U8*0.333 -> 0 | V13: =SUM(R13:U13) -> 0 | W13: =W8*0.333 -> 0 | X13: =X8*0.333 -> 0 | Y13: =Y8*0.333 -> 0 | Z13: =Z8*0.333 -> 0 | AA13: =SUM(W13:Z13) -> 0 | AB13: =AB8*AB14 -> 0 | AC13: =AC8*AC14 -> 0 | AD13: =AD8*AD14 -> 0 | AE13: =AE8*AE14 -> 0 | AF13: =SUM(AB13:AE13) -> 0 | AG13: =AG8*AG14 -> 0 | AH13: =AH8*AH14 -> 0 | AI13: =AI8*AI14 -> 0 | AJ13: =AJ8*AJ14 -> 0
A14: % of Revenue | C14: =IFERROR(COGS/Revenue,"N/A") -> N/A | D14: =IFERROR(COGS/Revenue,"N/A") -> N/A | E14: =IFERROR(COGS/Revenue,"N/A") -> N/A | F14: =IFERROR(COGS/Revenue,"N/A") -> N/A | G14: =IFERROR(COGS/Revenue,"N/A") -> N/A | H14: =IFERROR(COGS/Revenue,"N/A") -> N/A | I14: =IFERROR(COGS/Revenue,"N/A") -> N/A | J14: =IFERROR(COGS/Revenue,"N/A") -> N/A | ... AA14: =IFERROR(COGS/Revenue,"N/A") -> N/A | AB14: 0 | AC14: 0 | AD14: 0 | AE14: 0 | AF14: =IFERROR(COGS/Revenue,"N/A") -> N/A | AG14: 0 | AH14: 0 | AI14: 0 | AJ14: 0
A15: Gross profit | C15: =C8-C13 -> 0 | D15: =D8-D13 -> 0 | E15: =E8-E13 -> 0 | F15: =F8-F13 -> 0 | G15: =G8-G13 -> 0 | H15: =H8-H13 -> 0 | I15: =I8-I13 -> 0 | J15: =J8-J13 -> 0 | ... AJ15: =AJ8-AJ13 -> 0
A16: Gross margin | C16: =IFERROR(C15/C8,"N/A") -> N/A | D16: =IFERROR(D15/D8,"N/A") -> N/A | E16: =IFERROR(E15/E8,"N/A") -> N/A | F16: =IFERROR(F15/F8,"N/A") -> N/A | G16: =IFERROR(G15/G8,"N/A") -> N/A | H16: =IFERROR(H15/H8,"N/A") -> N/A | I16: =IFERROR(I15/I8,"N/A") -> N/A | J16: =IFERROR(J15/J8,"N/A") -> N/A | ... AJ16: =IFERROR(AJ15/AJ8,"N/A") -> N/A
AL18: ="Annual "&A19& " Sparkline (top line in $ change and bottom line in % of revenue): " -> Annual Sales and Marketing Sparkline (top line in $ change and bottom line in % of revenue):
A19: Sales and Marketing | C19: =0.1*Revenue -> 0 | D19: =0.1*Revenue -> 0 | E19: =0.1*Revenue -> 0 | F19: =0.1*Revenue -> 0 | G19: =SUM(C19:F19) -> 0 | H19: =0.1*Revenue -> 0 | I19: =0.1*Revenue -> 0 | J19: =0.1*Revenue -> 0 | K19: =0.1*Revenue -> 0 | L19: =SUM(H19:K19) -> 0 | M19: =0.1*Revenue -> 0 | N19: =0.1*Revenue -> 0 | O19: =0.1*Revenue -> 0 | P19: =0.1*Revenue -> 0 | Q19: =SUM(M19:P19) -> 0 | R19: =0.1*Revenue -> 0 | S19: =0.1*Revenue -> 0 | T19: =0.1*Revenue -> 0 | U19: =0.1*Revenue -> 0 | V19: =SUM(R19:U19) -> 0 | W19: =0.1*Revenue -> 0 | X19: =0.1*Revenue -> 0 | Y19: =0.1*Revenue -> 0 | Z19: =0.1*Revenue -> 0 | AA19: =SUM(W19:Z19) -> 0 | AB19: =AB20*Revenue -> 0 | AC19: =AC20*Revenue -> 0 | AD19: =AD20*Revenue -> 0 | AE19: =AE20*Revenue -> 0 | AF19: =SUM(AB19:AE19) -> 0 | AG19: =AG20*Revenue -> 0 | AH19: =AH20*Revenue -> 0 | AI19: =AI20*Revenue -> 0 | AJ19: =AJ20*Revenue -> 0
A20: % of Revenue | C20: =IFERROR(Sales_and_Marketing/Revenue,"N/A") -> N/A | D20: =IFERROR(Sales_and_Marketing/Revenue,"N/A") -> N/A | E20: =IFERROR(Sales_and_Marketing/Revenue,"N/A") -> N/A | F20: =IFERROR(Sales_and_Marketing/Revenue,"N/A") -> N/A | G20: N/A | H20: =IFERROR(Sales_and_Marketing/Revenue,"N/A") -> N/A | I20: =IFERROR(Sales_and_Marketing/Revenue,"N/A") -> N/A | J20: =IFERROR(Sales_and_Marketing/Revenue,"N/A") -> N/A | K20: =IFERROR(Sales_and_Marketing/Revenue,"N/A") -> N/A | L20: =IFERROR(Sales_and_Marketing/Revenue,"N/A") -> N/A | M20: =IFERROR(Sales_and_Marketing/Revenue,"N/A") -> N/A | N20: =IFERROR(Sales_and_Marketing/Revenue,"N/A") -> N/A | O20: =IFERROR(Sales_and_Marketing/Revenue,"N/A") -> N/A | ... AA20: =IFERROR(Sales_and_Marketing/Revenue,"N/A") -> N/A | AB20: 0 | AC20: 0 | AD20: 0 | AE20: 0 | AF20: =IFERROR(Sales_and_Marketing/Revenue,"N/A") -> N/A | AG20: 0 | AH20: 0 | AI20: 0 | AJ20: 0
A21: YOY change | G21: =IFERROR(G20/B20-1,"N/A") -> N/A | H21: =IFERROR(H19/C19-1,"N/A") -> N/A | I21: =IFERROR(I19/D19-1,"N/A") -> N/A | J21: =IFERROR(J19/E19-1,"N/A") -> N/A | K21: =IFERROR(K19/F19-1,"N/A") -> N/A | L21: =IFERROR(L19/G19-1,"N/A") -> N/A | M21: =IFERROR(M19/H19-1,"N/A") -> N/A | N21: =IFERROR(N19/I19-1,"N/A") -> N/A | O21: =IFERROR(O19/J19-1,"N/A") -> N/A | ... AF21: =IFERROR(AF19/AA19-1,"N/A") -> N/A | AG21: =IFERROR(AG19/AF19-1,"N/A") -> N/A | AH21: =IFERROR(AH19/AG19-1,"N/A") -> N/A | AI21: =IFERROR(AI19/AH19-1,"N/A") -> N/A | AJ21: =IFERROR(AJ19/AI19-1,"N/A") -> N/A
A22: QOQ change | D22: =IFERROR(D19/C19-1,"N/A") -> N/A | E22: =IFERROR(E19/D19-1,"N/A") -> N/A | F22: =IFERROR(F19/E19-1,"N/A") -> N/A | H22: =IFERROR(H19/F19-1,"N/A") -> N/A | I22: =IFERROR(I19/H19-1,"N/A") -> N/A | J22: =IFERROR(J19/I19-1,"N/A") -> N/A | K22: =IFERROR(K19/J19-1,"N/A") -> N/A | M22: =IFERROR(M19/K19-1,"N/A") -> N/A | N22: =IFERROR(N19/M19-1,"N/A") -> N/A | O22: =IFERROR(O19/N19-1,"N/A") -> N/A | P22: =IFERROR(P19/O19-1,"N/A") -> N/A | R22: =IFERROR(R19/P19-1,"N/A") -> N/A | S22: =IFERROR(S19/R19-1,"N/A") -> N/A | T22: =IFERROR(T19/S19-1,"N/A") -> N/A | U22: =IFERROR(U19/T19-1,"N/A") -> N/A | W22: =IFERROR(W19/U19-1,"N/A") -> N/A | X22: =IFERROR(X19/W19-1,"N/A") -> N/A | Y22: =IFERROR(Y19/X19-1,"N/A") -> N/A | Z22: =IFERROR(Z19/Y19-1,"N/A") -> N/A | AB22: =IFERROR(AB19/Z19-1,"N/A") -> N/A | AC22: =IFERROR(AC19/AB19-1,"N/A") -> N/A | AD22: =IFERROR(AD19/AC19-1,"N/A") -> N/A | AE22: =IFERROR(AE19/AD19-1,"N/A") -> N/A
A23: ="Quarterly "&A19&" Sparkline (click '2' above A1 to see it)." -> Quarterly Sales and Marketing Sparkline (click '2' above A1 to see it).
AL24: ="Annual "&A25& " Sparkline (top line in $ change and bottom line in % of revenue): " -> Annual Research and Development Sparkline (top line in $ change and bottom line in % of revenue):
A25: Research and Development | C25: =0.1*Revenue -> 0 | D25: =0.1*Revenue -> 0 | E25: =0.1*Revenue -> 0 | F25: =0.1*Revenue -> 0 | G25: =SUM(C25:F25) -> 0 | H25: =0.1*Revenue -> 0 | I25: =0.1*Revenue -> 0 | J25: =0.1*Revenue -> 0 | K25: =0.1*Revenue -> 0 | L25: =SUM(H25:K25) -> 0 | M25: =0.1*Revenue -> 0 | N25: =0.1*Revenue -> 0 | O25: =0.1*Revenue -> 0 | P25: =0.1*Revenue -> 0 | Q25: =SUM(M25:P25) -> 0 | R25: =0.1*Revenue -> 0 | S25: =0.1*Revenue -> 0 | T25: =0.1*Revenue -> 0 | U25: =0.1*Revenue -> 0 | V25: =SUM(R25:U25) -> 0 | W25: =0.1*Revenue -> 0 | X25: =0.1*Revenue -> 0 | Y25: =0.1*Revenue -> 0 | Z25: =0.1*Revenue -> 0 | AA25: =SUM(W25:Z25) -> 0 | AB25: =AB26*Revenue -> 0 | AC25: =AC26*Revenue -> 0 | AD25: =AD26*Revenue -> 0 | AE25: =AE26*Revenue -> 0 | AF25: =SUM(AB25:AE25) -> 0 | AG25: =AG26*Revenue -> 0 | AH25: =AH26*Revenue -> 0 | AI25: =AI26*Revenue -> 0 | AJ25: =AJ26*Revenue -> 0
A26: % of Revenue | C26: =IFERROR(Research_and_Development/Revenue,"N/A") -> N/A | D26: =IFERROR(Research_and_Development/Revenue,"N/A") -> N/A | E26: =IFERROR(Research_and_Development/Revenue,"N/A") -> N/A | F26: =IFERROR(Research_and_Development/Revenue,"N/A") -> N/A | G26: =IFERROR(Research_and_Development/Revenue,"N/A") -> N/A | H26: =IFERROR(Research_and_Development/Revenue,"N/A") -> N/A | I26: =IFERROR(Research_and_Development/Revenue,"N/A") -> N/A | J26: =IFERROR(Research_and_Development/Revenue,"N/A") -> N/A | ... AA26: =IFERROR(Research_and_Development/Revenue,"N/A") -> N/A | AB26: 0 | AC26: 0 | AD26: 0 | AE26: 0 | AF26: =IFERROR(Research_and_Development/Revenue,"N/A") -> N/A | AG26: 0 | AH26: 0 | AI26: 0 | AJ26: 0
A27: YOY change | G27: N/A | H27: =IFERROR(H25/C25-1,"N/A") -> N/A | I27: =IFERROR(I25/D25-1,"N/A") -> N/A | J27: =IFERROR(J25/E25-1,"N/A") -> N/A | K27: =IFERROR(K25/F25-1,"N/A") -> N/A | L27: =IFERROR(L25/G25-1,"N/A") -> N/A | M27: =IFERROR(M25/H25-1,"N/A") -> N/A | N27: =IFERROR(N25/I25-1,"N/A") -> N/A | O27: =IFERROR(O25/J25-1,"N/A") -> N/A | ... AF27: =IFERROR(AF25/AA25-1,"N/A") -> N/A | AG27: =IFERROR(AG25/AF25-1,"N/A") -> N/A | AH27: =IFERROR(AH25/AG25-1,"N/A") -> N/A | AI27: =IFERROR(AI25/AH25-1,"N/A") -> N/A | AJ27: =IFERROR(AJ25/AI25-1,"N/A") -> N/A
A28: QOQ change | D28: =IFERROR(D25/C25-1,"N/A") -> N/A | E28: =IFERROR(E25/D25-1,"N/A") -> N/A | F28: =IFERROR(F25/E25-1,"N/A") -> N/A | H28: =IFERROR(H25/F25-1,"N/A") -> N/A | I28: =IFERROR(I25/H25-1,"N/A") -> N/A | J28: =IFERROR(J25/I25-1,"N/A") -> N/A | K28: =IFERROR(K25/J25-1,"N/A") -> N/A | M28: =IFERROR(M25/K25-1,"N/A") -> N/A | N28: =IFERROR(N25/M25-1,"N/A") -> N/A | O28: =IFERROR(O25/N25-1,"N/A") -> N/A | P28: =IFERROR(P25/O25-1,"N/A") -> N/A | R28: =IFERROR(R25/P25-1,"N/A") -> N/A | S28: =IFERROR(S25/R25-1,"N/A") -> N/A | T28: =IFERROR(T25/S25-1,"N/A") -> N/A | U28: =IFERROR(U25/T25-1,"N/A") -> N/A | W28: =IFERROR(W25/U25-1,"N/A") -> N/A | X28: =IFERROR(X25/W25-1,"N/A") -> N/A | Y28: =IFERROR(Y25/X25-1,"N/A") -> N/A | Z28: =IFERROR(Z25/Y25-1,"N/A") -> N/A | AB28: =IFERROR(AB25/Z25-1,"N/A") -> N/A | AC28: =IFERROR(AC25/AB25-1,"N/A") -> N/A | AD28: =IFERROR(AD25/AC25-1,"N/A") -> N/A | AE28: =IFERROR(AE25/AD25-1,"N/A") -> N/A
A29: ="Quarterly "&A25&" Sparkline (click '2' above A1 to see it)." -> Quarterly Research and Development Sparkline (click '2' above A1 to see it).
AL30: ="Annual "&A31& " Sparkline (top line in $ change and bottom line in % of revenue): " -> Annual General and Administrative Sparkline (top line in $ change and bottom line in % of revenue):
A31: General and Administrative | C31: =0.1*Revenue -> 0 | D31: =0.1*Revenue -> 0 | E31: =0.1*Revenue -> 0 | F31: =0.1*Revenue -> 0 | G31: =SUM(C31:F31) -> 0 | H31: =0.1*Revenue -> 0 | I31: =0.1*Revenue -> 0 | J31: =0.1*Revenue -> 0 | K31: =0.1*Revenue -> 0 | L31: =SUM(H31:K31) -> 0 | M31: =0.1*Revenue -> 0 | N31: =0.1*Revenue -> 0 | O31: =0.1*Revenue -> 0 | P31: =0.1*Revenue -> 0 | Q31: =SUM(M31:P31) -> 0 | R31: =0.1*Revenue -> 0 | S31: =0.1*Revenue -> 0 | T31: =0.1*Revenue -> 0 | U31: =0.1*Revenue -> 0 | V31: =SUM(R31:U31) -> 0 | W31: =0.1*Revenue -> 0 | X31: =0.1*Revenue -> 0 | Y31: =0.1*Revenue -> 0 | Z31: =0.1*Revenue -> 0 | AA31: =SUM(W31:Z31) -> 0 | AB31: =0.05*Revenue -> 0 | AC31: =0.05*Revenue -> 0 | AD31: =0.05*Revenue -> 0 | AE31: =0.05*Revenue -> 0 | AF31: =SUM(AB31:AE31) -> 0 | AG31: =AG32*Revenue -> 0 | AH31: =AH32*Revenue -> 0 | AI31: =AI32*Revenue -> 0 | AJ31: =AJ32*Revenue -> 0
A32: % of Revenue | C32: =IFERROR(General_and_Administrative/Revenue,"N/A") -> N/A | D32: =IFERROR(General_and_Administrative/Revenue,"N/A") -> N/A | E32: =IFERROR(General_and_Administrative/Revenue,"N/A") -> N/A | F32: =IFERROR(General_and_Administrative/Revenue,"N/A") -> N/A | G32: =IFERROR(General_and_Administrative/Revenue,"N/A") -> N/A | H32: =IFERROR(General_and_Administrative/Revenue,"N/A") -> N/A | I32: =IFERROR(General_and_Administrative/Revenue,"N/A") -> N/A | J32: =IFERROR(General_and_Administrative/Revenue,"N/A") -> N/A | ... AF32: =IFERROR(General_and_Administrative/Revenue,"N/A") -> N/A | AG32: 0 | AH32: 0 | AI32: 0 | AJ32: 0
A33: YOY change | G33: N/A | H33: =IFERROR(H31/C31-1,"N/A") -> N/A | I33: =IFERROR(I31/D31-1,"N/A") -> N/A | J33: =IFERROR(J31/E31-1,"N/A") -> N/A | K33: =IFERROR(K31/F31-1,"N/A") -> N/A | L33: =IFERROR(L31/G31-1,"N/A") -> N/A | M33: =IFERROR(M31/H31-1,"N/A") -> N/A | N33: =IFERROR(N31/I31-1,"N/A") -> N/A | O33: =IFERROR(O31/J31-1,"N/A") -> N/A | ... AF33: =IFERROR(AF31/AA31-1,"N/A") -> N/A | AG33: =IFERROR(AG31/AF31-1,"N/A") -> N/A | AH33: =IFERROR(AH31/AG31-1,"N/A") -> N/A | AI33: =IFERROR(AI31/AH31-1,"N/A") -> N/A | AJ33: =IFERROR(AJ31/AI31-1,"N/A") -> N/A
A34: QOQ change | D34: =IFERROR(D31/C31-1,"N/A") -> N/A | E34: =IFERROR(E31/D31-1,"N/A") -> N/A | F34: =IFERROR(F31/E31-1,"N/A") -> N/A | H34: =IFERROR(H31/F31-1,"N/A") -> N/A | I34: =IFERROR(I31/H31-1,"N/A") -> N/A | J34: =IFERROR(J31/I31-1,"N/A") -> N/A | K34: =IFERROR(K31/J31-1,"N/A") -> N/A | M34: =IFERROR(M31/K31-1,"N/A") -> N/A | N34: =IFERROR(N31/M31-1,"N/A") -> N/A | O34: =IFERROR(O31/N31-1,"N/A") -> N/A | P34: =IFERROR(P31/O31-1,"N/A") -> N/A | R34: =IFERROR(R31/P31-1,"N/A") -> N/A | S34: =IFERROR(S31/R31-1,"N/A") -> N/A | T34: =IFERROR(T31/S31-1,"N/A") -> N/A | U34: =IFERROR(U31/T31-1,"N/A") -> N/A | W34: =IFERROR(W31/U31-1,"N/A") -> N/A | X34: =IFERROR(X31/W31-1,"N/A") -> N/A | Y34: =IFERROR(Y31/X31-1,"N/A") -> N/A | Z34: =IFERROR(Z31/Y31-1,"N/A") -> N/A | AB34: =IFERROR(AB31/Z31-1,"N/A") -> N/A | AC34: =IFERROR(AC31/AB31-1,"N/A") -> N/A | AD34: =IFERROR(AD31/AC31-1,"N/A") -> N/A | AE34: =IFERROR(AE31/AD31-1,"N/A") -> N/A
A35: ="Quarterly "&A31&" Sparkline (click '2' above A1 to see it)." -> Quarterly General and Administrative Sparkline (click '2' above A1 to see it).
AL36: ="Annual "&A37& " Sparkline (top line in $ change and bottom line in % of revenue): " -> Annual Depreciation Sparkline (top line in $ change and bottom line in % of revenue):
A37: Depreciation | C37: 0 | D37: 0 | E37: 0 | F37: 0 | G37: =SUM(C37:F37) -> 0 | H37: 0 | I37: 0 | J37: 0 | K37: 0 | L37: =SUM(H37:K37) -> 0 | M37: 0 | N37: 0 | O37: 0 | P37: 0 | Q37: =SUM(M37:P37) -> 0 | R37: 0 | S37: 0 | T37: 0 | U37: 0 | V37: =SUM(R37:U37) -> 0 | W37: 0 | X37: 0 | Y37: 0 | Z37: 0 | AA37: =SUM(W37:Z37) -> 0 | AB37: 0 | AC37: 0 | AD37: 0 | AE37: 0 | AF37: =SUM(AB37:AE37) -> 0 | AG37: =AG38*Revenue -> 0 | AH37: =AH38*Revenue -> 0 | AI37: =AI38*Revenue -> 0 | AJ37: =AJ38*Revenue -> 0
A38: % of Revenue | C38: =IFERROR(C37/Revenue,"N/A") -> N/A | D38: =IFERROR(D37/Revenue,"N/A") -> N/A | E38: =IFERROR(E37/Revenue,"N/A") -> N/A | F38: =IFERROR(F37/Revenue,"N/A") -> N/A | G38: =IFERROR(G37/Revenue,"N/A") -> N/A | H38: =IFERROR(H37/Revenue,"N/A") -> N/A | I38: =IFERROR(I37/Revenue,"N/A") -> N/A | J38: =IFERROR(J37/Revenue,"N/A") -> N/A | ... AF38: =IFERROR(AF37/Revenue,"N/A") -> N/A | AG38: 0 | AH38: 0 | AI38: 0 | AJ38: 0
A39: YOY change | G39: N/A | H39: =IFERROR(H37/C37-1,"N/A") -> N/A | I39: =IFERROR(I37/D37-1,"N/A") -> N/A | J39: =IFERROR(J37/E37-1,"N/A") -> N/A | K39: =IFERROR(K37/F37-1,"N/A") -> N/A | L39: =IFERROR(L37/G37-1,"N/A") -> N/A | M39: =IFERROR(M37/H37-1,"N/A") -> N/A | N39: =IFERROR(N37/I37-1,"N/A") -> N/A | O39: =IFERROR(O37/J37-1,"N/A") -> N/A | ... AF39: =IFERROR(AF37/AA37-1,"N/A") -> N/A | AG39: =IFERROR(AG37/AF37-1,"N/A") -> N/A | AH39: =IFERROR(AH37/AG37-1,"N/A") -> N/A | AI39: =IFERROR(AI37/AH37-1,"N/A") -> N/A | AJ39: =IFERROR(AJ37/AI37-1,"N/A") -> N/A
A40: QOQ change | D40: =IFERROR(D37/C37-1,"N/A") -> N/A | E40: =IFERROR(E37/D37-1,"N/A") -> N/A | F40: =IFERROR(F37/E37-1,"N/A") -> N/A | H40: =IFERROR(H37/F37-1,"N/A") -> N/A | I40: =IFERROR(I37/H37-1,"N/A") -> N/A | J40: =IFERROR(J37/I37-1,"N/A") -> N/A | K40: =IFERROR(K37/J37-1,"N/A") -> N/A | M40: =IFERROR(M37/K37-1,"N/A") -> N/A | N40: =IFERROR(N37/M37-1,"N/A") -> N/A | O40: =IFERROR(O37/N37-1,"N/A") -> N/A | P40: =IFERROR(P37/O37-1,"N/A") -> N/A | R40: =IFERROR(R37/P37-1,"N/A") -> N/A | S40: =IFERROR(S37/R37-1,"N/A") -> N/A | T40: =IFERROR(T37/S37-1,"N/A") -> N/A | U40: =IFERROR(U37/T37-1,"N/A") -> N/A | W40: =IFERROR(W37/U37-1,"N/A") -> N/A | X40: =IFERROR(X37/W37-1,"N/A") -> N/A | Y40: =IFERROR(Y37/X37-1,"N/A") -> N/A | Z40: =IFERROR(Z37/Y37-1,"N/A") -> N/A | AB40: =IFERROR(AB37/Z37-1,"N/A") -> N/A | AC40: =IFERROR(AC37/AB37-1,"N/A") -> N/A | AD40: =IFERROR(AD37/AC37-1,"N/A") -> N/A | AE40: =IFERROR(AE37/AD37-1,"N/A") -> N/A
A41: ="Quarterly "&A37&" Sparkline (click '2' above A1 to see it)." -> Quarterly Depreciation Sparkline (click '2' above A1 to see it).
...

Sheet Step 4 Balance Sheet
AK1: View Tips: For more space on your screen, please minimize the ribbon by clicking on the "^" on the top right-hand corner of your screen or zoom out using the view controls on the bottom-right hand corner of your screen.
A2: Welcome to Financial Modeling and Valuation Step 4 of 7! | L2: View Tips: For more space on your screen, please minimize the ribbon by clicking on the "^" on the top right-hand corner of your screen or zoom out using the view controls on the bottom-right hand corner of your screen.
A3: Change only the BLUE fonts, then go to Step 5 on the next tab.
A4: Orange Shaded Cells = Sparklines (for trend analysis) | AK4: 2013 - 2022 Annual TREND Sparklines
A5: Blue Fonts = hard coded (not calculated) | AK5: Note from Chris: Please make sure to close the groups by clicking on "1" to the left and slightly above column A or you will see quarterly numbers in this sparkline column.
A6: Green = links to data from another tab
A7: BALANCE SHEET $ Value in 000's | B7: ='Step 2 Revenue Forecast'!B6 -> 1Q13 | C7: ='Step 2 Revenue Forecast'!C6 -> 2Q13 | D7: ='Step 2 Revenue Forecast'!D6 -> 3Q13 | E7: ='Step 2 Revenue Forecast'!E6 -> 4Q13 | F7: ='Step 2 Revenue Forecast'!F6 -> 2013 | G7: ='Step 2 Revenue Forecast'!G6 -> 1Q14 | H7: ='Step 2 Revenue Forecast'!H6 -> 2Q14 | I7: ='Step 2 Revenue Forecast'!I6 -> 3Q14 | ... AI7: ='Step 2 Revenue Forecast'!AI6 -> 2022
A9: Current assets
A10: Cash and cash equivalents | B10: ='Step 5 Cash Flow Statement'!B25 -> 0 | C10: =B10+'Step 5 Cash Flow Statement'!C25 -> 0 | D10: =C10+'Step 5 Cash Flow Statement'!D25 -> 0 | E10: =D10+'Step 5 Cash Flow Statement'!E25 -> 0 | F10: =E10 -> 0 | G10: =E10+'Step 5 Cash Flow Statement'!G25 -> 0 | H10: =G10+'Step 5 Cash Flow Statement'!H25 -> 0 | I10: =H10+'Step 5 Cash Flow Statement'!I25 -> 0 | J10: =I10+'Step 5 Cash Flow Statement'!J25 -> 0 | K10: =J10 -> 0 | L10: =J10+'Step 5 Cash Flow Statement'!L25 -> 0 | M10: =L10+'Step 5 Cash Flow Statement'!M25 -> 0 | N10: =M10+'Step 5 Cash Flow Statement'!N25 -> 0 | O10: =N10+'Step 5 Cash Flow Statement'!O25 -> 0 | P10: =O10 -> 0 | Q10: =O10+'Step 5 Cash Flow Statement'!Q25 -> 0 | R10: =Q10+'Step 5 Cash Flow Statement'!R25 -> 0 | S10: =R10+'Step 5 Cash Flow Statement'!S25 -> 0 | T10: =S10+'Step 5 Cash Flow Statement'!T25 -> 0 | U10: =T10 -> 0 | V10: =T10+'Step 5 Cash Flow Statement'!V25 -> 0 | W10: =V10+'Step 5 Cash Flow Statement'!W25 -> 0 | X10: =W10+'Step 5 Cash Flow Statement'!X25 -> 0 | Y10: =X10+'Step 5 Cash Flow Statement'!Y25 -> 0 | Z10: =Y10 -> 0 | AA10: =Y10+'Step 5 Cash Flow Statement'!AA25 -> 0 | AB10: =AA10+'Step 5 Cash Flow Statement'!AB25 -> 0 | AC10: =AB10+'Step 5 Cash Flow Statement'!AC25 -> 0 | AD10: =AC10+'Step 5 Cash Flow Statement'!AD25 -> 0 | AE10: =AD10 -> 0 | AF10: =AD10+'Step 5 Cash Flow Statement'!AF25 -> 0 | AG10: =AF10+'Step 5 Cash Flow Statement'!AG25 -> 0 | AH10: =AG10+'Step 5 Cash Flow Statement'!AH25 -> 0 | AI10: =AH10+'Step 5 Cash Flow Statement'!AI25 -> 0
A11: Short-term investments | B11: 0 | C11: 0 | D11: 0 | E11: 0 | F11: =E11 -> 0 | G11: 0 | H11: 0 | I11: 0 | J11: 0 | K11: =J11 -> 0 | L11: 0 | M11: 0 | N11: 0 | O11: 0 | P11: =O11 -> 0 | Q11: 0 | R11: 0 | S11: 0 | T11: 0 | U11: =T11 -> 0 | V11: 0 | W11: 0 | X11: 0 | Y11: 0 | Z11: =Y11 -> 0 | AA11: 0 | AB11: 0 | AC11: 0 | AD11: 0 | AE11: =AD11 -> 0 | AF11: =AE11 -> 0 | AG11: =AF11 -> 0 | AH11: =AG11 -> 0 | AI11: =AH11 -> 0
A12: Accounts receivable | B12: 0 | C12: 0 | D12: 0 | E12: 0 | F12: =E12 -> 0 | G12: ='Step 3 Income Statement '!H8*0.1 -> 0 | H12: ='Step 3 Income Statement '!I8*0.1 -> 0 | I12: ='Step 3 Income Statement '!J8*0.1 -> 0 | J12: ='Step 3 Income Statement '!K8*0.1 -> 0 | K12: =J12 -> 0 | L12: ='Step 3 Income Statement '!M8*0.1 -> 0 | M12: ='Step 3 Income Statement '!N8*0.1 -> 0 | N12: ='Step 3 Income Statement '!O8*0.1 -> 0 | O12: ='Step 3 Income Statement '!P8*0.1 -> 0 | P12: =O12 -> 0 | Q12: ='Step 3 Income Statement '!R8*0.1 -> 0 | R12: ='Step 3 Income Statement '!S8*0.1 -> 0 | S12: ='Step 3 Income Statement '!T8*0.1 -> 0 | T12: ='Step 3 Income Statement '!U8*0.1 -> 0 | U12: =T12 -> 0 | V12: ='Step 3 Income Statement '!W8*0.1 -> 0 | W12: ='Step 3 Income Statement '!X8*0.1 -> 0 | X12: ='Step 3 Income Statement '!Y8*0.1 -> 0 | Y12: ='Step 3 Income Statement '!Z8*0.1 -> 0 | Z12: =Y12 -> 0 | AA12: ='Step 3 Income Statement '!AB8*0.1 -> 0 | AB12: ='Step 3 Income Statement '!AC8*0.1 -> 0 | AC12: ='Step 3 Income Statement '!AD8*0.1 -> 0 | AD12: ='Step 3 Income Statement '!AE8*0.1 -> 0 | AE12: =AD12 -> 0 | AF12: =AF13*'Step 3 Income Statement '!AG8 -> 0 | AG12: =AG13*'Step 3 Income Statement '!AH8 -> 0 | AH12: =AH13*'Step 3 Income Statement '!AI8 -> 0 | AI12: =AI13*'Step 3 Income Statement '!AJ8 -> 0
A13: Accounts Receivable as a % of revenue | B13: =IFERROR(B12/'Step 3 Income Statement '!C8,"N/A") -> N/A | C13: =IFERROR(C12/'Step 3 Income Statement '!D8,"N/A") -> N/A | D13: =IFERROR(D12/'Step 3 Income Statement '!E8,"N/A") -> N/A | E13: =IFERROR(E12/'Step 3 Income Statement '!F8,"N/A") -> N/A | F13: =IFERROR(F12/'Step 3 Income Statement '!G8,"N/A") -> N/A | G13: =IFERROR(G12/'Step 3 Income Statement '!H8,"N/A") -> N/A | H13: =IFERROR(H12/'Step 3 Income Statement '!I8,"N/A") -> N/A | I13: =IFERROR(I12/'Step 3 Income Statement '!J8,"N/A") -> N/A | J13: =IFERROR(J12/'Step 3 Income Statement '!K8,"N/A") -> N/A | K13: =J13 -> N/A | L13: =IFERROR(L12/'Step 3 Income Statement '!M8,"N/A") -> N/A | M13: =IFERROR(M12/'Step 3 Income Statement '!N8,"N/A") -> N/A | N13: =IFERROR(N12/'Step 3 Income Statement '!O8,"N/A") -> N/A | O13: =IFERROR(O12/'Step 3 Income Statement '!P8,"N/A") -> N/A | P13: =O13 -> N/A | Q13: =IFERROR(Q12/'Step 3 Income Statement '!R8,"N/A") -> N/A | R13: =IFERROR(R12/'Step 3 Income Statement '!S8,"N/A") -> N/A | S13: =IFERROR(S12/'Step 3 Income Statement '!T8,"N/A") -> N/A | T13: =IFERROR(T12/'Step 3 Income Statement '!U8,"N/A") -> N/A | U13: =T13 -> N/A | V13: =IFERROR(V12/'Step 3 Income Statement '!W8,"N/A") -> N/A | W13: =IFERROR(W12/'Step 3 Income Statement '!X8,"N/A") -> N/A | X13: =IFERROR(X12/'Step 3 Income Statement '!Y8,"N/A") -> N/A | Y13: =IFERROR(Y12/'Step 3 Income Statement '!Z8,"N/A") -> N/A | Z13: =Y13 -> N/A | AA13: =IFERROR(AA12/'Step 3 Income Statement '!AB8,"N/A") -> N/A | AB13: =IFERROR(AB12/'Step 3 Income Statement '!AC8,"N/A") -> N/A | AC13: =IFERROR(AC12/'Step 3 Income Statement '!AD8,"N/A") -> N/A | AD13: =IFERROR(AD12/'Step 3 Income Statement '!AE8,"N/A") -> N/A | AE13: =AD13 -> N/A | AF13: 0 | AG13: 0 | AH13: 0 | AI13: 0
A14: Inventory | B14: 0 | C14: 0 | D14: 0 | E14: 0 | F14: =E14 -> 0 | G14: 0 | H14: 0 | I14: 0 | J14: 0 | K14: =J14 -> 0 | L14: 0 | M14: 0 | N14: 0 | O14: 0 | P14: =O14 -> 0 | Q14: 0 | R14: 0 | S14: 0 | T14: 0 | U14: =T14 -> 0 | V14: 0 | W14: 0 | X14: 0 | Y14: 0 | Z14: =Y14 -> 0 | AA14: 0 | AB14: 0 | AC14: 0 | AD14: 0 | AE14: =AD14 -> 0 | AF14: =AF15*'Step 3 Income Statement '!AG8 -> 0 | AG14: =AG15*'Step 3 Income Statement '!AH8 -> 0 | AH14: =AH15*'Step 3 Income Statement '!AI8 -> 0 | AI14: =AI15*'Step 3 Income Statement '!AJ8 -> 0
A15: Inventory as a % of revenue | B15: =IFERROR(B14/'Step 3 Income Statement '!C8,"N/A") -> N/A | C15: =IFERROR(C14/'Step 3 Income Statement '!D8,"N/A") -> N/A | D15: =IFERROR(D14/'Step 3 Income Statement '!E8,"N/A") -> N/A | E15: =IFERROR(E14/'Step 3 Income Statement '!F8,"N/A") -> N/A | F15: =E15 -> N/A | G15: =IFERROR(G14/'Step 3 Income Statement '!H8,"N/A") -> N/A | H15: =IFERROR(H14/'Step 3 Income Statement '!I8,"N/A") -> N/A | I15: =IFERROR(I14/'Step 3 Income Statement '!J8,"N/A") -> N/A | J15: =IFERROR(J14/'Step 3 Income Statement '!K8,"N/A") -> N/A | K15: =J15 -> N/A | L15: =IFERROR(L14/'Step 3 Income Statement '!M8,"N/A") -> N/A | M15: =IFERROR(M14/'Step 3 Income Statement '!N8,"N/A") -> N/A | N15: =IFERROR(N14/'Step 3 Income Statement '!O8,"N/A") -> N/A | O15: =IFERROR(O14/'Step 3 Income Statement '!P8,"N/A") -> N/A | P15: =O15 -> N/A | Q15: =IFERROR(Q14/'Step 3 Income Statement '!R8,"N/A") -> N/A | R15: =IFERROR(R14/'Step 3 Income Statement '!S8,"N/A") -> N/A | S15: =IFERROR(S14/'Step 3 Income Statement '!T8,"N/A") -> N/A | T15: =IFERROR(T14/'Step 3 Income Statement '!U8,"N/A") -> N/A | U15: =T15 -> N/A | V15: =IFERROR(V14/'Step 3 Income Statement '!W8,"N/A") -> N/A | W15: =IFERROR(W14/'Step 3 Income Statement '!X8,"N/A") -> N/A | X15: =IFERROR(X14/'Step 3 Income Statement '!Y8,"N/A") -> N/A | Y15: =IFERROR(Y14/'Step 3 Income Statement '!Z8,"N/A") -> N/A | Z15: =Y15 -> N/A | AA15: =IFERROR(AA14/'Step 3 Income Statement '!AB8,"N/A") -> N/A | AB15: =IFERROR(AB14/'Step 3 Income Statement '!AC8,"N/A") -> N/A | AC15: =IFERROR(AC14/'Step 3 Income Statement '!AD8,"N/A") -> N/A | AD15: =IFERROR(AD14/'Step 3 Income Statement '!AE8,"N/A") -> N/A | AE15: =AD15 -> N/A | AF15: 0 | AG15: 0 | AH15: 0 | AI15: 0
A16: Total Current Assets | B16: =B14+B12+B11+B10 -> 0 | C16: =C14+C12+C11+C10 -> 0 | D16: =D14+D12+D11+D10 -> 0 | E16: =E14+E12+E11+E10 -> 0 | F16: =F14+F12+F11+F10 -> 0 | G16: =G14+G12+G11+G10 -> 0 | H16: =H14+H12+H11+H10 -> 0 | I16: =I14+I12+I11+I10 -> 0 | ... AI16: =AI14+AI12+AI11+AI10 -> 0
A17: Long Term Assets
A18: **Equipment we own, net of accumulated depreciation and inclusive of capex. | B18: =B21-B20 -> 0 | C18: =B18-C20+C21 -> 0 | D18: =C18-D20+D21 -> 0 | E18: =D18-E20+E21 -> 0 | F18: =E18 -> 0 | G18: =E18-G20+G21 -> 0 | H18: =G18-H20+H21 -> 0 | I18: =H18-I20+I21 -> 0 | J18: =I18-J20+J21 -> 0 | K18: =J18 -> 0 | L18: =J18-L20+L21 -> 0 | M18: =L18-M20+M21 -> 0 | N18: =M18-N20+N21 -> 0 | O18: =N18-O20+O21 -> 0 | P18: =O18 -> 0 | Q18: =O18-Q20+Q21 -> 0 | R18: =Q18-R20+R21 -> 0 | S18: =R18-S20+S21 -> 0 | T18: =S18-T20+T21 -> 0 | U18: =T18 -> 0 | V18: =T18-V20+V21 -> 0 | W18: =V18-W20+W21 -> 0 | X18: =W18-X20+X21 -> 0 | Y18: =X18-Y20+Y21 -> 0 | Z18: =Y18 -> 0 | AA18: =Y18-AA20+AA21 -> 0 | AB18: =AA18-AB20+AB21 -> 0 | AC18: =AB18-AC20+AC21 -> 0 | AD18: =AC18-AD20+AD21 -> 0 | AE18: =AD18 -> 0 | AF18: =AD18-AF20+AF21 -> 0 | AG18: =AF18-AG20+AG21 -> 0 | AH18: =AG18-AH20+AH21 -> 0 | AI18: =AH18-AI20+AI21 -> 0
A19: Here is How We Calculate Capex (same as Purchase of Equipment)
A20: Depreciation (linked to the Income Statement) | B20: ='Step 3 Income Statement '!C37 -> 0 | C20: ='Step 3 Income Statement '!D37 -> 0 | D20: ='Step 3 Income Statement '!E37 -> 0 | E20: ='Step 3 Income Statement '!F37 -> 0 | F20: ='Step 3 Income Statement '!G37 -> 0 | G20: ='Step 3 Income Statement '!H37 -> 0 | H20: ='Step 3 Income Statement '!I37 -> 0 | I20: ='Step 3 Income Statement '!J37 -> 0 | ... AI20: ='Step 3 Income Statement '!AJ37 -> 0
A21: Capex (we need to calculate this here as it feeds into the C.F. Statement) | B21: 0 | C21: 0 | D21: 0 | E21: 0 | F21: =E21 -> 0 | G21: 0 | H21: 0 | I21: 0 | J21: 0 | K21: =J21 -> 0 | L21: 0 | M21: 0 | N21: 0 | O21: 0 | P21: =O21 -> 0 | Q21: 0 | R21: 0 | S21: 0 | T21: 0 | U21: =T21 -> 0 | V21: 0 | W21: 0 | X21: 0 | Y21: 0 | Z21: =Y21 -> 0 | AA21: 0 | AB21: 0 | AC21: 0 | AD21: 0 | AE21: =AD21 -> 0 | AF21: 0 | AG21: 0 | AH21: 0 | AI21: 0
A22: Capex as a % of revenue | B22: =IFERROR(B21/'Step 3 Income Statement '!C8,"N/A") -> N/A | C22: =IFERROR(C21/'Step 3 Income Statement '!D8,"N/A") -> N/A | D22: =IFERROR(D21/'Step 3 Income Statement '!E8,"N/A") -> N/A | E22: =IFERROR(E21/'Step 3 Income Statement '!F8,"N/A") -> N/A | F22: =IFERROR(F21/'Step 3 Income Statement '!G8,"N/A") -> N/A | G22: =IFERROR(G21/'Step 3 Income Statement '!H8,"N/A") -> N/A | H22: =IFERROR(H21/'Step 3 Income Statement '!I8,"N/A") -> N/A | I22: =IFERROR(I21/'Step 3 Income Statement '!J8,"N/A") -> N/A | ... AI22: =IFERROR(AI21/'Step 3 Income Statement '!AJ8,"N/A") -> N/A
A24: Total Long Term Assets | B24: =B18 -> 0 | C24: =C18 -> 0 | D24: =D18 -> 0 | E24: =E18 -> 0 | F24: =E24 -> 0 | G24: =G18 -> 0 | H24: =H18 -> 0 | I24: =I18 -> 0 | J24: =J18 -> 0 | K24: =J24 -> 0 | L24: =L18 -> 0 | M24: =M18 -> 0 | N24: =N18 -> 0 | O24: =O18 -> 0 | P24: =O24 -> 0 | Q24: =Q18 -> 0 | R24: =R18 -> 0 | S24: =S18 -> 0 | T24: =T18 -> 0 | U24: =T24 -> 0 | V24: =V18 -> 0 | W24: =W18 -> 0 | X24: =X18 -> 0 | Y24: =Y18 -> 0 | Z24: =Y24 -> 0 | AA24: =AA18 -> 0 | AB24: =AB18 -> 0 | AC24: =AC18 -> 0 | AD24: =AD18 -> 0 | AE24: =AD24 -> 0 | AF24: =AF18 -> 0 | AG24: =AG18 -> 0 | AH24: =AH18 -> 0 | AI24: =AI18 -> 0
A25: TOTAL ASSETS | B25: =B24+B16 -> 0 | C25: =C24+C16 -> 0 | D25: =D24+D16 -> 0 | E25: =E24+E16 -> 0 | F25: =E25 -> 0 | G25: =G24+G16 -> 0 | H25: =H24+H16 -> 0 | I25: =I24+I16 -> 0 | J25: =J24+J16 -> 0 | K25: =J25 -> 0 | L25: =L24+L16 -> 0 | M25: =M24+M16 -> 0 | N25: =N24+N16 -> 0 | O25: =O24+O16 -> 0 | P25: =O25 -> 0 | Q25: =Q24+Q16 -> 0 | R25: =R24+R16 -> 0 | S25: =S24+S16 -> 0 | T25: =T24+T16 -> 0 | U25: =T25 -> 0 | V25: =V24+V16 -> 0 | W25: =W24+W16 -> 0 | X25: =X24+X16 -> 0 | Y25: =Y24+Y16 -> 0 | Z25: =Y25 -> 0 | AA25: =AA24+AA16 -> 0 | AB25: =AB24+AB16 -> 0 | AC25: =AC24+AC16 -> 0 | AD25: =AD24+AD16 -> 0 | AE25: =AD25 -> 0 | AF25: =AF24+AF16 -> 0 | AG25: =AG24+AG16 -> 0 | AH25: =AH24+AH16 -> 0 | AI25: =AI24+AI16 -> 0
A28: Current liabilities
A29: Accounts payable | B29: 0 | C29: 0 | D29: 0 | E29: 0 | F29: =E29 -> 0 | G29: ='Step 3 Income Statement '!H8*0.1 -> 0 | H29: ='Step 3 Income Statement '!I8*0.1 -> 0 | I29: ='Step 3 Income Statement '!J8*0.1 -> 0 | J29: ='Step 3 Income Statement '!K8*0.1 -> 0 | K29: =J29 -> 0 | L29: ='Step 3 Income Statement '!M8*0.1 -> 0 | M29: ='Step 3 Income Statement '!N8*0.1 -> 0 | N29: ='Step 3 Income Statement '!O8*0.1 -> 0 | O29: ='Step 3 Income Statement '!P8*0.1 -> 0 | P29: =O29 -> 0 | Q29: ='Step 3 Income Statement '!R8*0.1 -> 0 | R29: ='Step 3 Income Statement '!S8*0.1 -> 0 | S29: ='Step 3 Income Statement '!T8*0.1 -> 0 | T29: ='Step 3 Income Statement '!U8*0.1 -> 0 | U29: =T29 -> 0 | V29: ='Step 3 Income Statement '!W8*0.1 -> 0 | W29: ='Step 3 Income Statement '!X8*0.1 -> 0 | X29: ='Step 3 Income Statement '!Y8*0.1 -> 0 | Y29: ='Step 3 Income Statement '!Z8*0.1 -> 0 | Z29: =Y29 -> 0 | AA29: ='Step 3 Income Statement '!AB8*0.1 -> 0 | AB29: ='Step 3 Income Statement '!AC8*0.1 -> 0 | AC29: ='Step 3 Income Statement '!AD8*0.1 -> 0 | AD29: ='Step 3 Income Statement '!AE8*0.1 -> 0 | AE29: =AD29 -> 0 | AF29: ='Step 3 Income Statement '!AG8*0.1 -> 0 | AG29: ='Step 3 Income Statement '!AH8*0.1 -> 0 | AH29: ='Step 3 Income Statement '!AI8*0.1 -> 0 | AI29: ='Step 3 Income Statement '!AJ8*0.1 -> 0
A30: Accounts Payable as a % of revenue | B30: =IFERROR(B29/'Step 3 Income Statement '!C8,"N/A") -> N/A | C30: =IFERROR(C29/'Step 3 Income Statement '!D8,"N/A") -> N/A | D30: =IFERROR(D29/'Step 3 Income Statement '!E8,"N/A") -> N/A | E30: =IFERROR(E29/'Step 3 Income Statement '!F8,"N/A") -> N/A | F30: =IFERROR(F29/'Step 3 Income Statement '!G8,"N/A") -> N/A | G30: =IFERROR(G29/'Step 3 Income Statement '!H8,"N/A") -> N/A | H30: =IFERROR(H29/'Step 3 Income Statement '!I8,"N/A") -> N/A | I30: =IFERROR(I29/'Step 3 Income Statement '!J8,"N/A") -> N/A | J30: =IFERROR(J29/'Step 3 Income Statement '!K8,"N/A") -> N/A | K30: =J30 -> N/A | L30: =IFERROR(L29/'Step 3 Income Statement '!M8,"N/A") -> N/A | M30: =IFERROR(M29/'Step 3 Income Statement '!N8,"N/A") -> N/A | N30: =IFERROR(N29/'Step 3 Income Statement '!O8,"N/A") -> N/A | O30: =IFERROR(O29/'Step 3 Income Statement '!P8,"N/A") -> N/A | P30: =IFERROR(P29/'Step 3 Income Statement '!Q8,"N/A") -> N/A | Q30: =IFERROR(Q29/'Step 3 Income Statement '!R8,"N/A") -> N/A | R30: =IFERROR(R29/'Step 3 Income Statement '!S8,"N/A") -> N/A | S30: =IFERROR(S29/'Step 3 Income Statement '!T8,"N/A") -> N/A | T30: =IFERROR(T29/'Step 3 Income Statement '!U8,"N/A") -> N/A | U30: =T30 -> N/A | V30: =IFERROR(V29/'Step 3 Income Statement '!W8,"N/A") -> N/A | W30: =IFERROR(W29/'Step 3 Income Statement '!X8,"N/A") -> N/A | X30: =IFERROR(X29/'Step 3 Income Statement '!Y8,"N/A") -> N/A | Y30: =IFERROR(Y29/'Step 3 Income Statement '!Z8,"N/A") -> N/A | Z30: =Y30 -> N/A | AA30: =IFERROR(AA29/'Step 3 Income Statement '!AB8,"N/A") -> N/A | AB30: =IFERROR(AB29/'Step 3 Income Statement '!AC8,"N/A") -> N/A | AC30: =IFERROR(AC29/'Step 3 Income Statement '!AD8,"N/A") -> N/A | AD30: =IFERROR(AD29/'Step 3 Income Statement '!AE8,"N/A") -> N/A | AE30: =AD30 -> N/A | AF30: =IFERROR(AF29/'Step 3 Income Statement '!AG8,"N/A") -> N/A | AG30: =IFERROR(AG29/'Step 3 Income Statement '!AH8,"N/A") -> N/A | AH30: =IFERROR(AH29/'Step 3 Income Statement '!AI8,"N/A") -> N/A | AI30: =IFERROR(AI29/'Step 3 Income Statement '!AJ8,"N/A") -> N/A
A31: Short-term debt | B31: 0 | C31: 0 | D31: 0 | E31: 0 | F31: =E31 -> 0 | G31: 0 | H31: 0 | I31: 0 | J31: 0 | K31: =J31 -> 0 | L31: 0 | M31: 0 | N31: 0 | O31: 0 | P31: =O31 -> 0 | Q31: 0 | R31: 0 | S31: 0 | T31: 0 | U31: =T31 -> 0 | V31: 0 | W31: 0 | X31: 0 | Y31: 0 | Z31: =Y31 -> 0 | AA31: 0 | AB31: 0 | AC31: 0 | AD31: 0 | AE31: =AD31 -> 0 | AF31: =AE31 -> 0 | AG31: =AF31 -> 0 | AH31: =AG31 -> 0 | AI31: =AH31 -> 0
A32: Total Current Liabilities | B32: =B29+B31 -> 0 | C32: =C29+C31 -> 0 | D32: =D29+D31 -> 0 | E32: =E29+E31 -> 0 | F32: =F29+F31 -> 0 | G32: =G29+G31 -> 0 | H32: =H29+H31 -> 0 | I32: =I29+I31 -> 0 | ... AI32: =AI29+AI31 -> 0
A33: Long Term Liabilities
A34: Long-term debt | B34: 0 | C34: 0 | D34: 0 | E34: 0 | F34: =E34 -> 0 | G34: 0 | H34: 0 | I34: 0 | J34: 0 | K34: =J34 -> 0 | L34: 0 | M34: 0 | N34: 0 | O34: 0 | P34: =O34 -> 0 | Q34: 0 | R34: 0 | S34: 0 | T34: 0 | U34: =T34 -> 0 | V34: 0 | W34: 0 | X34: 0 | Y34: 0 | Z34: =Y34 -> 0 | AA34: 0 | AB34: 0 | AC34: 0 | AD34: 0 | AE34: =AD34 -> 0 | AF34: =AE34 -> 0 | AG34: =AF34 -> 0 | AH34: =AG34 -> 0 | AI34: =AH34 -> 0
A35: Total Long Term Liabilities | B35: =B34 -> 0 | C35: =C34 -> 0 | D35: =D34 -> 0 | E35: =E34 -> 0 | F35: =E35 -> 0 | G35: =G34 -> 0 | H35: =H34 -> 0 | I35: =I34 -> 0 | J35: =J34 -> 0 | K35: =J35 -> 0 | L35: =L34 -> 0 | M35: =M34 -> 0 | N35: =N34 -> 0 | O35: =O34 -> 0 | P35: =O35 -> 0 | Q35: =Q34 -> 0 | R35: =R34 -> 0 | S35: =S34 -> 0 | T35: =T34 -> 0 | U35: =T35 -> 0 | V35: =V34 -> 0 | W35: =W34 -> 0 | X35: =X34 -> 0 | Y35: =Y34 -> 0 | Z35: =Y35 -> 0 | AA35: =AA34 -> 0 | AB35: =AB34 -> 0 | AC35: =AC34 -> 0 | AD35: =AD34 -> 0 | AE35: =AD35 -> 0 | AF35: =AF34 -> 0 | AG35: =AG34 -> 0 | AH35: =AH34 -> 0 | AI35: =AI34 -> 0
A36: TOTAL LIABILITIES | B36: =B35+B32 -> 0 | C36: =C35+C32 -> 0 | D36: =D35+D32 -> 0 | E36: =E35+E32 -> 0 | F36: =E36 -> 0 | G36: =G35+G32 -> 0 | H36: =H35+H32 -> 0 | I36: =I35+I32 -> 0 | J36: =J35+J32 -> 0 | K36: =J36 -> 0 | L36: =L35+L32 -> 0 | M36: =M35+M32 -> 0 | N36: =N35+N32 -> 0 | O36: =O35+O32 -> 0 | P36: =O36 -> 0 | Q36: =Q35+Q32 -> 0 | R36: =R35+R32 -> 0 | S36: =S35+S32 -> 0 | T36: =T35+T32 -> 0 | U36: =T36 -> 0 | V36: =V35+V32 -> 0 | W36: =W35+W32 -> 0 | X36: =X35+X32 -> 0 | Y36: =Y35+Y32 -> 0 | Z36: =Y36 -> 0 | AA36: =AA35+AA32 -> 0 | AB36: =AB35+AB32 -> 0 | AC36: =AC35+AC32 -> 0 | AD36: =AD35+AD32 -> 0 | AE36: =AD36 -> 0 | AF36: =AF35+AF32 -> 0 | AG36: =AG35+AG32 -> 0 | AH36: =AH35+AH32 -> 0 | AI36: =AI35+AI32 -> 0
A39: Retained Earnings | B39: ='Step 3 Income Statement '!C58 -> 0 | C39: =IFERROR(B39+'Step 3 Income Statement '!D58,"N/A") -> 0 | D39: =IFERROR(C39+'Step 3 Income Statement '!E58,"N/A") -> 0 | E39: =IFERROR(D39+'Step 3 Income Statement '!F58,"N/A") -> 0 | F39: =E39 -> 0 | G39: =IFERROR(E39+'Step 3 Income Statement '!H58,"N/A") -> 0 | H39: =IFERROR(G39+'Step 3 Income Statement '!I58,"N/A") -> 0 | I39: =IFERROR(H39+'Step 3 Income Statement '!J58,"N/A") -> 0 | J39: =IFERROR(I39+'Step 3 Income Statement '!K58,"N/A") -> 0 | K39: =J39 -> 0 | L39: =IFERROR(J39+'Step 3 Income Statement '!M58,"N/A") -> 0 | M39: =IFERROR(L39+'Step 3 Income Statement '!N58,"N/A") -> 0 | N39: =IFERROR(M39+'Step 3 Income Statement '!O58,"N/A") -> 0 | O39: =IFERROR(N39+'Step 3 Income Statement '!P58,"N/A") -> 0 | P39: =O39 -> 0 | Q39: =IFERROR(O39+'Step 3 Income Statement '!R58,"N/A") -> 0 | R39: =IFERROR(Q39+'Step 3 Income Statement '!S58,"N/A") -> 0 | S39: =IFERROR(R39+'Step 3 Income Statement '!T58,"N/A") -> 0 | T39: =IFERROR(S39+'Step 3 Income Statement '!U58,"N/A") -> 0 | U39: =T39 -> 0 | V39: =IFERROR(T39+'Step 3 Income Statement '!W58,"N/A") -> 0 | W39: =IFERROR(V39+'Step 3 Income Statement '!X58,"N/A") -> 0 | X39: =IFERROR(W39+'Step 3 Income Statement '!Y58,"N/A") -> 0 | Y39: =IFERROR(X39+'Step 3 Income Statement '!Z58,"N/A") -> 0 | Z39: =Y39 -> 0 | AA39: =IFERROR(Y39+'Step 3 Income Statement '!AB58,"N/A") -> 0 | AB39: =IFERROR(AA39+'Step 3 Income Statement '!AC58,"N/A") -> 0 | AC39: =IFERROR(AB39+'Step 3 Income Statement '!AD58,"N/A") -> 0 | AD39: =IFERROR(AC39+'Step 3 Income Statement '!AE58,"N/A") -> 0 | AE39: =AD39 -> 0 | AF39: =AE39+'Step 3 Income Statement '!AG58 -> 0 | AG39: =AF39+'Step 3 Income Statement '!AH58 -> 0 | AH39: =AG39+'Step 3 Income Statement '!AI58 -> 0 | AI39: =AH39+'Step 3 Income Statement '!AJ58 -> 0
A40: Common Shares | B40: 0 | C40: 0 | D40: 0 | E40: 0 | F40: =E40 -> 0 | G40: 0 | H40: 0 | I40: 0 | J40: 0 | K40: =J40 -> 0 | L40: 0 | M40: 0 | N40: 0 | O40: 0 | P40: =O40 -> 0 | Q40: 0 | R40: 0 | S40: 0 | T40: 0 | U40: =T40 -> 0 | V40: 0 | W40: 0 | X40: 0 | Y40: 0 | Z40: =Y40 -> 0 | AA40: 0 | AB40: 0 | AC40: 0 | AD40: 0 | AE40: =AD40 -> 0 | AF40: =AE40 -> 0 | AG40: =AF40 -> 0 | AH40: =AG40 -> 0 | AI40: =AH40 -> 0
A41: Additional Paid-in-Capital | B41: 0 | C41: =B41 -> 0 | D41: =C41 -> 0 | E41: =D41 -> 0 | F41: =E41 -> 0 | G41: =F41 -> 0 | H41: =G41 -> 0 | I41: =H41 -> 0 | J41: =I41 -> 0 | ... AI41: =AH41 -> 0
A42: TOTAL SHAREHOLDER'S EQUITY | B42: =SUM(B39:B40) -> 0 | C42: =SUM(C39:C40) -> 0 | D42: =SUM(D39:D40) -> 0 | E42: =SUM(E39:E40) -> 0 | F42: =E42 -> 0 | G42: =SUM(G39:G40) -> 0 | H42: =SUM(H39:H40) -> 0 | I42: =SUM(I39:I40) -> 0 | J42: =SUM(J39:J40) -> 0 | K42: =J42 -> 0 | L42: =SUM(L39:L40) -> 0 | M42: =SUM(M39:M40) -> 0 | N42: =SUM(N39:N40) -> 0 | O42: =SUM(O39:O40) -> 0 | P42: =O42 -> 0 | Q42: =SUM(Q39:Q40) -> 0 | R42: =SUM(R39:R40) -> 0 | S42: =SUM(S39:S40) -> 0 | T42: =SUM(T39:T40) -> 0 | U42: =T42 -> 0 | V42: =SUM(V39:V40) -> 0 | W42: =SUM(W39:W40) -> 0 | X42: =SUM(X39:X40) -> 0 | Y42: =SUM(Y39:Y40) -> 0 | Z42: =Y42 -> 0 | AA42: =SUM(AA39:AA40) -> 0 | AB42: =SUM(AB39:AB40) -> 0 | AC42: =SUM(AC39:AC40) -> 0 | AD42: =SUM(AD39:AD40) -> 0 | AE42: =AD42 -> 0 | AF42: =SUM(AF39:AF40) -> 0 | AG42: =SUM(AG39:AG40) -> 0 | AH42: =SUM(AH39:AH40) -> 0 | AI42: =SUM(AI39:AI40) -> 0
A44: TOTAL LIABILITIES AND SHAREHOLDERS' EQUITY | B44: =B42+B36 -> 0 | C44: =C42+C36 -> 0 | D44: =D42+D36 -> 0 | E44: =E42+E36 -> 0 | F44: =E44 -> 0 | G44: =G42+G36 -> 0 | H44: =H42+H36 -> 0 | I44: =I42+I36 -> 0 | J44: =J42+J36 -> 0 | K44: =J44 -> 0 | L44: =L42+L36 -> 0 | M44: =M42+M36 -> 0 | N44: =N42+N36 -> 0 | O44: =O42+O36 -> 0 | P44: =O44 -> 0 | Q44: =Q42+Q36 -> 0 | R44: =R42+R36 -> 0 | S44: =S42+S36 -> 0 | T44: =T42+T36 -> 0 | U44: =T44 -> 0 | V44: =V42+V36 -> 0 | W44: =W42+W36 -> 0 | X44: =X42+X36 -> 0 | Y44: =Y42+Y36 -> 0 | Z44: =Y44 -> 0 | AA44: =AA42+AA36 -> 0 | AB44: =AB42+AB36 -> 0 | AC44: =AC42+AC36 -> 0 | AD44: =AD42+AD36 -> 0 | AE44: =AD44 -> 0 | AF44: =AF42+AF36 -> 0 | AG44: =AG42+AG36 -> 0 | AH44: =AH42+AH36 -> 0 | AI44: =AI42+AI36 -> 0
A45: Do Assets = Liabilities + Equity? | B45: =IF(ROUND(B44,6)=ROUND(B25,6),"YES","NO") -> YES | C45: =IF(ROUND(C44,6)=ROUND(C25,6),"YES","NO") -> YES | D45: =IF(ROUND(D44,6)=ROUND(D25,6),"YES","NO") -> YES | E45: =IF(ROUND(E44,6)=ROUND(E25,6),"YES","NO") -> YES | F45: =IF(ROUND(F44,6)=ROUND(F25,6),"YES","NO") -> YES | G45: =IF(ROUND(G44,6)=ROUND(G25,6),"YES","NO") -> YES | H45: =IF(ROUND(H44,6)=ROUND(H25,6),"YES","NO") -> YES | I45: =IF(ROUND(I44,6)=ROUND(I25,6),"YES","NO") -> YES | ... AI45: =IF(ROUND(AI44,6)=ROUND(AI25,6),"YES","NO") -> YES
B46: =B44-B25 -> 0 | C46: =C44-C25 -> 0 | D46: =D44-D25 -> 0 | E46: =E44-E25 -> 0 | F46: =F44-F25 -> 0 | G46: =G44-G25 -> 0 | H46: =H44-H25 -> 0 | I46: =I44-I25 -> 0 | ... AI46: =AI44-AI25 -> 0
A49: ** The equipment that we own is equal to the amount of equipment we owned in the previous quarter minus the amount that the equipment has depreciated since the previous quarter PLUS the capex we spent to buy more equipment. Please see the math/logic in the cells in the Equipment section above under Long Term Assets. Thanks
...

Sheet Step 5 Cash Flow Statement
AK1: View Tips: For more space on your screen, please minimize the ribbon by clicking on the "^" on the top right-hand corner of your screen or zoom out using the view controls on the bottom-right hand corner of your screen.
A2: Welcome to Financial Modeling and Valuation Step 5 of 7! | B2: The Cash Flow Statement Forecasts are mainly from the Balance Sheet (i.e., 'working capital', capex, debt and equity) and the Income Statement (net income and depreciation).
A3: Nothing to do here! Please move on to Step 6 on the next tab. | AK3: 2013 - 2022 Annual TREND Sparklines
A4: Orange Shaded Cells = Sparklines (for trend analysis) | AK4: Note from Chris: Please make sure to close the groups by clicking on "1" to the left and slightly above column A or you will see quarterly numbers in this sparkline column.
A5: Green = links to data from another tab
A6: CASH FLOW STATEMENT $ Value in 000's | B6: ='Step 2 Revenue Forecast'!B6 -> 1Q13 | C6: ='Step 2 Revenue Forecast'!C6 -> 2Q13 | D6: ='Step 2 Revenue Forecast'!D6 -> 3Q13 | E6: ='Step 2 Revenue Forecast'!E6 -> 4Q13 | F6: ='Step 2 Revenue Forecast'!F6 -> 2013 | G6: ='Step 2 Revenue Forecast'!G6 -> 1Q14 | H6: ='Step 2 Revenue Forecast'!H6 -> 2Q14 | I6: ='Step 2 Revenue Forecast'!I6 -> 3Q14 | ... AI6: ='Step 2 Revenue Forecast'!AI6 -> 2022
A7: Operating Activities
A8: Net Income | B8: ='Step 3 Income Statement '!C58 -> 0 | C8: ='Step 3 Income Statement '!D58 -> 0 | D8: ='Step 3 Income Statement '!E58 -> 0 | E8: ='Step 3 Income Statement '!F58 -> 0 | F8: =SUM(B8:E8) -> 0 | G8: ='Step 3 Income Statement '!H58 -> 0 | H8: ='Step 3 Income Statement '!I58 -> 0 | I8: ='Step 3 Income Statement '!J58 -> 0 | J8: ='Step 3 Income Statement '!K58 -> 0 | K8: =SUM(G8:J8) -> 0 | L8: ='Step 3 Income Statement '!M58 -> 0 | M8: ='Step 3 Income Statement '!N58 -> 0 | N8: ='Step 3 Income Statement '!O58 -> 0 | O8: ='Step 3 Income Statement '!P58 -> 0 | P8: =SUM(L8:O8) -> 0 | Q8: ='Step 3 Income Statement '!R58 -> 0 | R8: ='Step 3 Income Statement '!S58 -> 0 | S8: ='Step 3 Income Statement '!T58 -> 0 | T8: ='Step 3 Income Statement '!U58 -> 0 | U8: =SUM(Q8:T8) -> 0 | V8: ='Step 3 Income Statement '!W58 -> 0 | W8: ='Step 3 Income Statement '!X58 -> 0 | X8: ='Step 3 Income Statement '!Y58 -> 0 | Y8: ='Step 3 Income Statement '!Z58 -> 0 | Z8: =SUM(V8:Y8) -> 0 | AA8: ='Step 3 Income Statement '!AB58 -> 0 | AB8: ='Step 3 Income Statement '!AC58 -> 0 | AC8: ='Step 3 Income Statement '!AD58 -> 0 | AD8: ='Step 3 Income Statement '!AE58 -> 0 | AE8: =SUM(AA8:AD8) -> 0 | AF8: ='Step 3 Income Statement '!AG58 -> 0 | AG8: ='Step 3 Income Statement '!AH58 -> 0 | AH8: ='Step 3 Income Statement '!AI58 -> 0 | AI8: ='Step 3 Income Statement '!AJ58 -> 0
A9: Increase in Depreciation (+) | B9: ='Step 3 Income Statement '!C37 -> 0 | C9: ='Step 3 Income Statement '!D37 -> 0 | D9: ='Step 3 Income Statement '!E37 -> 0 | E9: ='Step 3 Income Statement '!F37 -> 0 | F9: =SUM(B9:E9) -> 0 | G9: ='Step 3 Income Statement '!H37 -> 0 | H9: ='Step 3 Income Statement '!I37 -> 0 | I9: ='Step 3 Income Statement '!J37 -> 0 | J9: ='Step 3 Income Statement '!K37 -> 0 | K9: =SUM(G9:J9) -> 0 | L9: ='Step 3 Income Statement '!M37 -> 0 | M9: ='Step 3 Income Statement '!N37 -> 0 | N9: ='Step 3 Income Statement '!O37 -> 0 | O9: ='Step 3 Income Statement '!P37 -> 0 | P9: =SUM(L9:O9) -> 0 | Q9: ='Step 3 Income Statement '!R37 -> 0 | R9: ='Step 3 Income Statement '!S37 -> 0 | S9: ='Step 3 Income Statement '!T37 -> 0 | T9: ='Step 3 Income Statement '!U37 -> 0 | U9: =SUM(Q9:T9) -> 0 | V9: ='Step 3 Income Statement '!W37 -> 0 | W9: ='Step 3 Income Statement '!X37 -> 0 | X9: ='Step 3 Income Statement '!Y37 -> 0 | Y9: ='Step 3 Income Statement '!Z37 -> 0 | Z9: =SUM(V9:Y9) -> 0 | AA9: ='Step 3 Income Statement '!AB37 -> 0 | AB9: ='Step 3 Income Statement '!AC37 -> 0 | AC9: ='Step 3 Income Statement '!AD37 -> 0 | AD9: ='Step 3 Income Statement '!AE37 -> 0 | AE9: =SUM(AA9:AD9) -> 0 | AF9: ='Step 3 Income Statement '!AG37 -> 0 | AG9: ='Step 3 Income Statement '!AH37 -> 0 | AH9: ='Step 3 Income Statement '!AI37 -> 0 | AI9: ='Step 3 Income Statement '!AJ37 -> 0
A10: Increase in Accounts Receivable (-) | B10: N/A | C10: ='Step 4 Balance Sheet'!B12-'Step 4 Balance Sheet'!C12 -> 0 | D10: ='Step 4 Balance Sheet'!C12-'Step 4 Balance Sheet'!D12 -> 0 | E10: ='Step 4 Balance Sheet'!D12-'Step 4 Balance Sheet'!E12 -> 0 | F10: ='Step 4 Balance Sheet'!E12-'Step 4 Balance Sheet'!F12 -> 0 | G10: ='Step 4 Balance Sheet'!F12-'Step 4 Balance Sheet'!G12 -> 0 | H10: ='Step 4 Balance Sheet'!G12-'Step 4 Balance Sheet'!H12 -> 0 | I10: ='Step 4 Balance Sheet'!H12-'Step 4 Balance Sheet'!I12 -> 0 | J10: ='Step 4 Balance Sheet'!I12-'Step 4 Balance Sheet'!J12 -> 0 | ... AI10: ='Step 4 Balance Sheet'!AH12-'Step 4 Balance Sheet'!AI12 -> 0
A11: Increase in Inventory (-) | B11: N/A | C11: ='Step 4 Balance Sheet'!B14-'Step 4 Balance Sheet'!C14 -> 0 | D11: ='Step 4 Balance Sheet'!C14-'Step 4 Balance Sheet'!D14 -> 0 | E11: ='Step 4 Balance Sheet'!D14-'Step 4 Balance Sheet'!E14 -> 0 | F11: ='Step 4 Balance Sheet'!E14-'Step 4 Balance Sheet'!F14 -> 0 | G11: ='Step 4 Balance Sheet'!F14-'Step 4 Balance Sheet'!G14 -> 0 | H11: ='Step 4 Balance Sheet'!G14-'Step 4 Balance Sheet'!H14 -> 0 | I11: ='Step 4 Balance Sheet'!H14-'Step 4 Balance Sheet'!I14 -> 0 | J11: ='Step 4 Balance Sheet'!I14-'Step 4 Balance Sheet'!J14 -> 0 | ... AI11: ='Step 4 Balance Sheet'!AH14-'Step 4 Balance Sheet'!AI14 -> 0
